<?xml version="1.0" encoding="UTF-8"?>
<testng-results ignored="1" total="3" passed="0" failed="2" skipped="0">
  <reporter-output>
  </reporter-output>
  <suite started-at="2025-02-17T01:41:30 IST" name="Default suite" finished-at="2025-02-17T01:42:12 IST" duration-ms="42093">
    <groups>
      <group name="Negative TestCases">
        <method signature="DB_LoginTest.inValidUserLogin(java.lang.String,java.lang.String)[pri:0, instance:nnd.TestCases.DB_LoginTest@420745d7]" name="inValidUserLogin" class="nnd.TestCases.DB_LoginTest"/>
      </group> <!-- Negative TestCases -->
    </groups>
    <test started-at="2025-02-17T01:41:30 IST" name="Default test" finished-at="2025-02-17T01:42:12 IST" duration-ms="42093">
      <class name="nnd.TestCases.DB_LoginTest">
        <test-method is-config="true" signature="setUp(java.lang.reflect.Method,org.testng.ITestContext)[pri:0, instance:nnd.TestCases.DB_LoginTest@420745d7]" started-at="2025-02-17T01:41:31 IST" name="setUp" finished-at="2025-02-17T01:41:35 IST" duration-ms="3174" status="PASS">
          <params>
            <param index="0">
              <value>
                <![CDATA[public void nnd.TestCases.DB_LoginTest.inValidUserLogin(java.lang.String,java.lang.String) throws org.apache.poi.openxml4j.exceptions.InvalidFormatException,java.io.IOException,java.lang.InterruptedException]]>
              </value>
            </param>
            <param index="1">
              <value>
                <![CDATA[org.testng.TestRunner@82560b6]]>
              </value>
            </param>
          </params>
          <reporter-output>
          </reporter-output>
        </test-method> <!-- setUp -->
        <test-method signature="inValidUserLogin(java.lang.String,java.lang.String)[pri:0, instance:nnd.TestCases.DB_LoginTest@420745d7]" started-at="2025-02-17T01:41:35 IST" name="inValidUserLogin" description="LoginTest_TC01 inValid User Login" data-provider="invalidloginData" finished-at="2025-02-17T01:41:43 IST" duration-ms="8458" status="FAIL">
          <params>
            <param index="0">
              <value>
                <![CDATA[dhanINV01]]>
              </value>
            </param>
            <param index="1">
              <value>
                <![CDATA[dhanINV#01]]>
              </value>
            </param>
          </params>
          <exception class="java.lang.AssertionError">
            <message>
              <![CDATA[Log in failed expected [Log in successful.] but found [User does not exist.]]]>
            </message>
            <full-stacktrace>
              <![CDATA[java.lang.AssertionError: Log in failed expected [Log in successful.] but found [User does not exist.]
at org.testng.Assert.fail(Assert.java:99)
at org.testng.Assert.failNotEquals(Assert.java:1037)
at org.testng.Assert.assertEqualsImpl(Assert.java:140)
at org.testng.Assert.assertEquals(Assert.java:122)
at org.testng.Assert.assertEquals(Assert.java:629)
at nnd.Pages.DB_LoginPage.loginAlertHandle(DB_LoginPage.java:126)
at nnd.TestCases.DB_LoginTest.inValidUserLogin(DB_LoginTest.java:87)
at java.base/jdk.internal.reflect.DirectMethodHandleAccessor.invoke(DirectMethodHandleAccessor.java:103)
at java.base/java.lang.reflect.Method.invoke(Method.java:580)
at org.testng.internal.MethodInvocationHelper.invokeMethod(MethodInvocationHelper.java:133)
at org.testng.internal.TestInvoker.invokeMethod(TestInvoker.java:598)
at org.testng.internal.TestInvoker.invokeTestMethod(TestInvoker.java:173)
at org.testng.internal.MethodRunner.runInSequence(MethodRunner.java:46)
at org.testng.internal.TestInvoker$MethodInvocationAgent.invoke(TestInvoker.java:824)
at org.testng.internal.TestInvoker.invokeTestMethods(TestInvoker.java:146)
at org.testng.internal.TestMethodWorker.invokeTestMethods(TestMethodWorker.java:146)
at org.testng.internal.TestMethodWorker.run(TestMethodWorker.java:128)
at java.base/java.util.ArrayList.forEach(ArrayList.java:1596)
at org.testng.TestRunner.privateRun(TestRunner.java:794)
at org.testng.TestRunner.run(TestRunner.java:596)
at org.testng.SuiteRunner.runTest(SuiteRunner.java:377)
at org.testng.SuiteRunner.runSequentially(SuiteRunner.java:371)
at org.testng.SuiteRunner.privateRun(SuiteRunner.java:332)
at org.testng.SuiteRunner.run(SuiteRunner.java:276)
at org.testng.SuiteRunnerWorker.runSuite(SuiteRunnerWorker.java:53)
at org.testng.SuiteRunnerWorker.run(SuiteRunnerWorker.java:96)
at org.testng.TestNG.runSuitesSequentially(TestNG.java:1212)
at org.testng.TestNG.runSuitesLocally(TestNG.java:1134)
at org.testng.TestNG.runSuites(TestNG.java:1063)
at org.testng.TestNG.run(TestNG.java:1031)
at org.testng.remote.AbstractRemoteTestNG.run(AbstractRemoteTestNG.java:115)
at org.testng.remote.RemoteTestNG.initAndRun(RemoteTestNG.java:293)
at org.testng.remote.RemoteTestNG.main(RemoteTestNG.java:91)
]]>
            </full-stacktrace>
          </exception> <!-- java.lang.AssertionError -->
          <reporter-output>
          </reporter-output>
        </test-method> <!-- inValidUserLogin -->
        <test-method is-config="true" signature="tearDown()[pri:0, instance:nnd.TestCases.DB_LoginTest@420745d7]" started-at="2025-02-17T01:41:45 IST" name="tearDown" finished-at="2025-02-17T01:41:45 IST" duration-ms="178" status="PASS">
          <reporter-output>
          </reporter-output>
        </test-method> <!-- tearDown -->
        <test-method is-config="true" signature="setUp(java.lang.reflect.Method,org.testng.ITestContext)[pri:0, instance:nnd.TestCases.DB_LoginTest@420745d7]" started-at="2025-02-17T01:41:45 IST" name="setUp" finished-at="2025-02-17T01:42:02 IST" duration-ms="17386" status="PASS">
          <params>
            <param index="0">
              <value>
                <![CDATA[public void nnd.TestCases.DB_LoginTest.inValidUserLogin(java.lang.String,java.lang.String) throws org.apache.poi.openxml4j.exceptions.InvalidFormatException,java.io.IOException,java.lang.InterruptedException]]>
              </value>
            </param>
            <param index="1">
              <value>
                <![CDATA[org.testng.TestRunner@82560b6]]>
              </value>
            </param>
          </params>
          <reporter-output>
          </reporter-output>
        </test-method> <!-- setUp -->
        <test-method signature="inValidUserLogin(java.lang.String,java.lang.String)[pri:0, instance:nnd.TestCases.DB_LoginTest@420745d7]" started-at="2025-02-17T01:42:02 IST" name="inValidUserLogin" description="LoginTest_TC01 inValid User Login" data-provider="invalidloginData" finished-at="2025-02-17T01:42:11 IST" duration-ms="8430" status="FAIL">
          <params>
            <param index="0">
              <value>
                <![CDATA[dhanINV02]]>
              </value>
            </param>
            <param index="1">
              <value>
                <![CDATA[dhanINV#02]]>
              </value>
            </param>
          </params>
          <exception class="java.lang.AssertionError">
            <message>
              <![CDATA[Log in failed expected [Log in successful.] but found [User does not exist.]]]>
            </message>
            <full-stacktrace>
              <![CDATA[java.lang.AssertionError: Log in failed expected [Log in successful.] but found [User does not exist.]
at org.testng.Assert.fail(Assert.java:99)
at org.testng.Assert.failNotEquals(Assert.java:1037)
at org.testng.Assert.assertEqualsImpl(Assert.java:140)
at org.testng.Assert.assertEquals(Assert.java:122)
at org.testng.Assert.assertEquals(Assert.java:629)
at nnd.Pages.DB_LoginPage.loginAlertHandle(DB_LoginPage.java:126)
at nnd.TestCases.DB_LoginTest.inValidUserLogin(DB_LoginTest.java:87)
at java.base/jdk.internal.reflect.DirectMethodHandleAccessor.invoke(DirectMethodHandleAccessor.java:103)
at java.base/java.lang.reflect.Method.invoke(Method.java:580)
at org.testng.internal.MethodInvocationHelper.invokeMethod(MethodInvocationHelper.java:133)
at org.testng.internal.TestInvoker.invokeMethod(TestInvoker.java:598)
at org.testng.internal.TestInvoker.invokeTestMethod(TestInvoker.java:173)
at org.testng.internal.MethodRunner.runInSequence(MethodRunner.java:46)
at org.testng.internal.TestInvoker$MethodInvocationAgent.invoke(TestInvoker.java:824)
at org.testng.internal.TestInvoker.invokeTestMethods(TestInvoker.java:146)
at org.testng.internal.TestMethodWorker.invokeTestMethods(TestMethodWorker.java:146)
at org.testng.internal.TestMethodWorker.run(TestMethodWorker.java:128)
at java.base/java.util.ArrayList.forEach(ArrayList.java:1596)
at org.testng.TestRunner.privateRun(TestRunner.java:794)
at org.testng.TestRunner.run(TestRunner.java:596)
at org.testng.SuiteRunner.runTest(SuiteRunner.java:377)
at org.testng.SuiteRunner.runSequentially(SuiteRunner.java:371)
at org.testng.SuiteRunner.privateRun(SuiteRunner.java:332)
at org.testng.SuiteRunner.run(SuiteRunner.java:276)
at org.testng.SuiteRunnerWorker.runSuite(SuiteRunnerWorker.java:53)
at org.testng.SuiteRunnerWorker.run(SuiteRunnerWorker.java:96)
at org.testng.TestNG.runSuitesSequentially(TestNG.java:1212)
at org.testng.TestNG.runSuitesLocally(TestNG.java:1134)
at org.testng.TestNG.runSuites(TestNG.java:1063)
at org.testng.TestNG.run(TestNG.java:1031)
at org.testng.remote.AbstractRemoteTestNG.run(AbstractRemoteTestNG.java:115)
at org.testng.remote.RemoteTestNG.initAndRun(RemoteTestNG.java:293)
at org.testng.remote.RemoteTestNG.main(RemoteTestNG.java:91)
]]>
            </full-stacktrace>
          </exception> <!-- java.lang.AssertionError -->
          <reporter-output>
          </reporter-output>
        </test-method> <!-- inValidUserLogin -->
        <test-method is-config="true" signature="tearDown()[pri:0, instance:nnd.TestCases.DB_LoginTest@420745d7]" started-at="2025-02-17T01:42:12 IST" name="tearDown" finished-at="2025-02-17T01:42:12 IST" duration-ms="128" status="PASS">
          <reporter-output>
          </reporter-output>
        </test-method> <!-- tearDown -->
      </class> <!-- nnd.TestCases.DB_LoginTest -->
    </test> <!-- Default test -->
  </suite> <!-- Default suite -->
</testng-results>
