<?xml version="1.0" encoding="UTF-8"?>
<testng-results ignored="0" total="2" passed="0" failed="2" skipped="0">
  <reporter-output>
  </reporter-output>
  <suite started-at="2025-02-15T01:41:35 IST" name="Default suite" finished-at="2025-02-15T01:41:54 IST" duration-ms="18630">
    <groups>
    </groups>
    <test started-at="2025-02-15T01:41:35 IST" name="Default test" finished-at="2025-02-15T01:41:54 IST" duration-ms="18630">
      <class name="nnd.TestCases.RegisterTest">
        <test-method is-config="true" signature="setUp(java.lang.reflect.Method,org.testng.ITestContext)[pri:0, instance:nnd.TestCases.RegisterTest@199e4c2b]" started-at="2025-02-15T01:41:37 IST" name="setUp" finished-at="2025-02-15T01:41:40 IST" duration-ms="3075" status="PASS">
          <params>
            <param index="0">
              <value>
                <![CDATA[public void nnd.TestCases.RegisterTest.validUserSignUp(java.lang.String,java.lang.String) throws java.lang.InterruptedException]]>
              </value>
            </param>
            <param index="1">
              <value>
                <![CDATA[org.testng.TestRunner@44aff76b]]>
              </value>
            </param>
          </params>
          <reporter-output>
          </reporter-output>
        </test-method> <!-- setUp -->
        <test-method signature="validUserSignUp(java.lang.String,java.lang.String)[pri:0, instance:nnd.TestCases.RegisterTest@199e4c2b]" started-at="2025-02-15T01:41:40 IST" name="validUserSignUp" description="valid user sign Up " data-provider="testData" finished-at="2025-02-15T01:41:45 IST" duration-ms="5491" status="FAIL">
          <params>
            <param index="0">
              <value>
                <![CDATA[dhan01]]>
              </value>
            </param>
            <param index="1">
              <value>
                <![CDATA[dhan@01]]>
              </value>
            </param>
          </params>
          <exception class="java.lang.AssertionError">
            <message>
              <![CDATA[Signup failed expected [Sign up successful.] but found [This user already exist.]]]>
            </message>
            <full-stacktrace>
              <![CDATA[java.lang.AssertionError: Signup failed expected [Sign up successful.] but found [This user already exist.]
at org.testng.Assert.fail(Assert.java:99)
at org.testng.Assert.failNotEquals(Assert.java:1037)
at org.testng.Assert.assertEqualsImpl(Assert.java:140)
at org.testng.Assert.assertEquals(Assert.java:122)
at org.testng.Assert.assertEquals(Assert.java:629)
at nnd.Pages.RegisterPage.clickSignUp(RegisterPage.java:70)
at nnd.TestCases.RegisterTest.validUserSignUp(RegisterTest.java:57)
at java.base/jdk.internal.reflect.DirectMethodHandleAccessor.invoke(DirectMethodHandleAccessor.java:103)
at java.base/java.lang.reflect.Method.invoke(Method.java:580)
at org.testng.internal.MethodInvocationHelper.invokeMethod(MethodInvocationHelper.java:133)
at org.testng.internal.TestInvoker.invokeMethod(TestInvoker.java:598)
at org.testng.internal.TestInvoker.invokeTestMethod(TestInvoker.java:173)
at org.testng.internal.MethodRunner.runInSequence(MethodRunner.java:46)
at org.testng.internal.TestInvoker$MethodInvocationAgent.invoke(TestInvoker.java:824)
at org.testng.internal.TestInvoker.invokeTestMethods(TestInvoker.java:146)
at org.testng.internal.TestMethodWorker.invokeTestMethods(TestMethodWorker.java:146)
at org.testng.internal.TestMethodWorker.run(TestMethodWorker.java:128)
at java.base/java.util.ArrayList.forEach(ArrayList.java:1596)
at org.testng.TestRunner.privateRun(TestRunner.java:794)
at org.testng.TestRunner.run(TestRunner.java:596)
at org.testng.SuiteRunner.runTest(SuiteRunner.java:377)
at org.testng.SuiteRunner.runSequentially(SuiteRunner.java:371)
at org.testng.SuiteRunner.privateRun(SuiteRunner.java:332)
at org.testng.SuiteRunner.run(SuiteRunner.java:276)
at org.testng.SuiteRunnerWorker.runSuite(SuiteRunnerWorker.java:53)
at org.testng.SuiteRunnerWorker.run(SuiteRunnerWorker.java:96)
at org.testng.TestNG.runSuitesSequentially(TestNG.java:1212)
at org.testng.TestNG.runSuitesLocally(TestNG.java:1134)
at org.testng.TestNG.runSuites(TestNG.java:1063)
at org.testng.TestNG.run(TestNG.java:1031)
at org.testng.remote.AbstractRemoteTestNG.run(AbstractRemoteTestNG.java:115)
at org.testng.remote.RemoteTestNG.initAndRun(RemoteTestNG.java:293)
at org.testng.remote.RemoteTestNG.main(RemoteTestNG.java:91)
]]>
            </full-stacktrace>
          </exception> <!-- java.lang.AssertionError -->
          <reporter-output>
          </reporter-output>
        </test-method> <!-- validUserSignUp -->
        <test-method is-config="true" signature="tearDown()[pri:0, instance:nnd.TestCases.RegisterTest@199e4c2b]" started-at="2025-02-15T01:41:45 IST" name="tearDown" finished-at="2025-02-15T01:41:46 IST" duration-ms="326" status="PASS">
          <reporter-output>
          </reporter-output>
        </test-method> <!-- tearDown -->
        <test-method is-config="true" signature="setUp(java.lang.reflect.Method,org.testng.ITestContext)[pri:0, instance:nnd.TestCases.RegisterTest@199e4c2b]" started-at="2025-02-15T01:41:46 IST" name="setUp" finished-at="2025-02-15T01:41:48 IST" duration-ms="2190" status="PASS">
          <params>
            <param index="0">
              <value>
                <![CDATA[public void nnd.TestCases.RegisterTest.validUserSignUp(java.lang.String,java.lang.String) throws java.lang.InterruptedException]]>
              </value>
            </param>
            <param index="1">
              <value>
                <![CDATA[org.testng.TestRunner@44aff76b]]>
              </value>
            </param>
          </params>
          <reporter-output>
          </reporter-output>
        </test-method> <!-- setUp -->
        <test-method signature="validUserSignUp(java.lang.String,java.lang.String)[pri:0, instance:nnd.TestCases.RegisterTest@199e4c2b]" started-at="2025-02-15T01:41:48 IST" name="validUserSignUp" description="valid user sign Up " data-provider="testData" finished-at="2025-02-15T01:41:53 IST" duration-ms="5471" status="FAIL">
          <params>
            <param index="0">
              <value>
                <![CDATA[dhan6000]]>
              </value>
            </param>
            <param index="1">
              <value>
                <![CDATA[dhan@6000]]>
              </value>
            </param>
          </params>
          <exception class="java.lang.AssertionError">
            <message>
              <![CDATA[Signup failed expected [Sign up successful.] but found [This user already exist.]]]>
            </message>
            <full-stacktrace>
              <![CDATA[java.lang.AssertionError: Signup failed expected [Sign up successful.] but found [This user already exist.]
at org.testng.Assert.fail(Assert.java:99)
at org.testng.Assert.failNotEquals(Assert.java:1037)
at org.testng.Assert.assertEqualsImpl(Assert.java:140)
at org.testng.Assert.assertEquals(Assert.java:122)
at org.testng.Assert.assertEquals(Assert.java:629)
at nnd.Pages.RegisterPage.clickSignUp(RegisterPage.java:70)
at nnd.TestCases.RegisterTest.validUserSignUp(RegisterTest.java:57)
at java.base/jdk.internal.reflect.DirectMethodHandleAccessor.invoke(DirectMethodHandleAccessor.java:103)
at java.base/java.lang.reflect.Method.invoke(Method.java:580)
at org.testng.internal.MethodInvocationHelper.invokeMethod(MethodInvocationHelper.java:133)
at org.testng.internal.TestInvoker.invokeMethod(TestInvoker.java:598)
at org.testng.internal.TestInvoker.invokeTestMethod(TestInvoker.java:173)
at org.testng.internal.MethodRunner.runInSequence(MethodRunner.java:46)
at org.testng.internal.TestInvoker$MethodInvocationAgent.invoke(TestInvoker.java:824)
at org.testng.internal.TestInvoker.invokeTestMethods(TestInvoker.java:146)
at org.testng.internal.TestMethodWorker.invokeTestMethods(TestMethodWorker.java:146)
at org.testng.internal.TestMethodWorker.run(TestMethodWorker.java:128)
at java.base/java.util.ArrayList.forEach(ArrayList.java:1596)
at org.testng.TestRunner.privateRun(TestRunner.java:794)
at org.testng.TestRunner.run(TestRunner.java:596)
at org.testng.SuiteRunner.runTest(SuiteRunner.java:377)
at org.testng.SuiteRunner.runSequentially(SuiteRunner.java:371)
at org.testng.SuiteRunner.privateRun(SuiteRunner.java:332)
at org.testng.SuiteRunner.run(SuiteRunner.java:276)
at org.testng.SuiteRunnerWorker.runSuite(SuiteRunnerWorker.java:53)
at org.testng.SuiteRunnerWorker.run(SuiteRunnerWorker.java:96)
at org.testng.TestNG.runSuitesSequentially(TestNG.java:1212)
at org.testng.TestNG.runSuitesLocally(TestNG.java:1134)
at org.testng.TestNG.runSuites(TestNG.java:1063)
at org.testng.TestNG.run(TestNG.java:1031)
at org.testng.remote.AbstractRemoteTestNG.run(AbstractRemoteTestNG.java:115)
at org.testng.remote.RemoteTestNG.initAndRun(RemoteTestNG.java:293)
at org.testng.remote.RemoteTestNG.main(RemoteTestNG.java:91)
]]>
            </full-stacktrace>
          </exception> <!-- java.lang.AssertionError -->
          <reporter-output>
          </reporter-output>
        </test-method> <!-- validUserSignUp -->
        <test-method is-config="true" signature="tearDown()[pri:0, instance:nnd.TestCases.RegisterTest@199e4c2b]" started-at="2025-02-15T01:41:54 IST" name="tearDown" finished-at="2025-02-15T01:41:54 IST" duration-ms="222" status="PASS">
          <reporter-output>
          </reporter-output>
        </test-method> <!-- tearDown -->
      </class> <!-- nnd.TestCases.RegisterTest -->
    </test> <!-- Default test -->
  </suite> <!-- Default suite -->
</testng-results>
